<?xml version="1.0" ?>
<!-- =================================================================================== -->
<!-- |    This document was autogenerated by xacro from /home/tzt/agilex_ws/agilex_ws/src/moveit_config/dh_robotics_ag95_model/urdf/dh_robotics_ag95_model.xacro | -->
<!-- |    EDITING THIS FILE BY HAND IS NOT RECOMMENDED                                 | -->
<!-- =================================================================================== -->
<robot name="dh_robotics_ag95_model">
  <link name="dh_robotics_ag95_base_link">
    <inertial>
      <origin rpy="0 0 0" xyz="0 0 0"/>
      <mass value="0.22652"/>
      <inertia ixx="0.00020005" ixy="-4.2442E-10" ixz="-2.9069E-10" iyy="0.00017832" iyz="-3.4402E-08" izz="0.00013478"/>
    </inertial>
    <visual>
      <origin rpy="0 0 0" xyz="0 0 0"/>
      <geometry>
        <mesh filename="../meshes/ag95/base_link.STL" scale="1 1 1"/>
      </geometry>
      <material name="">
        <color rgba="0.1 0.1 0.1 1"/>
      </material>
    </visual>
    <collision>
      <origin rpy="0 0 0" xyz="0 0 0"/>
      <geometry>
        <mesh filename="../meshes/ag95/base_link.STL"/>
      </geometry>
    </collision>
  </link>
  <link name="left_crank">
    <inertial>
      <origin rpy="0 0 0" xyz="-0.000200000000003065 0.0199435877845359 0.0292245259211331"/>
      <mass value="0.00853198276973456"/>
      <inertia ixx="2.89328108496468E-06" ixy="-1.57935047237397E-19" ixz="-1.93980378593255E-19" iyy="1.86719750325683E-06" iyz="-1.21858577871576E-06" izz="1.21905238907251E-06"/>
    </inertial>
    <visual>
      <origin rpy="0 0 0" xyz="0 0 0"/>
      <geometry>
        <mesh filename="../meshes/ag95/link_crank.STL" scale="1 1 1"/>
      </geometry>
      <material name="">
        <color rgba="0.1 0.1 0.1 1"/>
      </material>
    </visual>
    <collision>
      <origin rpy="0 0 0" xyz="0 0 0"/>
      <geometry>
        <mesh filename="../meshes/ag95/link_crank.STL" scale="1 1 1"/>
      </geometry>
    </collision>
  </link>
  <link name="left_rod">
    <inertial>
      <origin rpy="0 0 0" xyz="0.00030115855001899 0.0373907951953854 -0.0208027427000385"/>
      <mass value="0.022614240507152"/>
      <inertia ixx="1.52518312458174E-05" ixy="9.76583423954399E-10" ixz="-5.43838577022588E-10" iyy="6.17694243867776E-06" iyz="6.78636130740228E-06" izz="1.16494917907219E-05"/>
    </inertial>
    <visual>
      <origin rpy="0 0 0" xyz="0 0 0"/>
      <geometry>
        <mesh filename="../meshes/ag95/link_rod.STL" scale="1 1 1"/>
      </geometry>
      <material name="">
        <color rgba="0.1 0.1 0.1 1"/>
      </material>
    </visual>
    <collision>
      <origin rpy="0 0 0" xyz="0 0 0"/>
      <geometry>
        <mesh filename="../meshes/ag95/link_rod.STL" scale="1 1 1"/>
      </geometry>
    </collision>
  </link>
  <link name="left_distal_phalanx">
    <inertial>
      <origin rpy="0 0 0" xyz="0.000299999999999317 0.0160078233491243 -0.0136945669206257"/>
      <mass value="0.0104003125914103"/>
      <inertia ixx="2.71909453810972E-06" ixy="1.35402465472579E-21" ixz="-7.1817349065269E-22" iyy="7.69100314106116E-07" iyz="6.74715432769696E-07" izz="2.30315190420171E-06"/>
    </inertial>
    <visual>
      <origin rpy="0 0 0" xyz="0 0 0"/>
      <geometry>
        <mesh filename="../meshes/ag95/link_distal_phalanx.STL" scale="1 1 1"/>
      </geometry>
      <material name="">
        <color rgba="0.792156862745098 0.819607843137255 0.933333333333333 1"/>
      </material>
    </visual>
    <collision>
      <origin rpy="0 0 0" xyz="0 0 0"/>
      <geometry>
        <mesh filename="../meshes/ag95/link_distal_phalanx.STL" scale="1 1 1"/>
      </geometry>
    </collision>
  </link>
  <link name="left_proximal_phalanx">
    <inertial>
      <origin rpy="0 0 0" xyz="0.000123011831763771 0.0507850843201817 0.00103968640075166"/>
      <mass value="0.0271177346495152"/>
      <inertia ixx="2.61910379223783E-05" ixy="-2.43616858946494E-07" ixz="-6.37789906117123E-09" iyy="2.8270243746167E-06" iyz="-5.37200748039765E-07" izz="2.83695868220296E-05"/>
    </inertial>
    <visual>
      <origin rpy="0 0 0" xyz="0 0 0"/>
      <geometry>
        <mesh filename="../meshes/ag95/link_proximal_phalanx.STL" scale="1 1 1"/>
      </geometry>
      <material name="">
        <color rgba="0.1 0.1 0.1 1"/>
      </material>
    </visual>
    <collision>
      <origin rpy="0 0 0" xyz="0 0 0"/>
      <geometry>
        <mesh filename="../meshes/ag95/link_proximal_phalanx.STL" scale="1 1 1"/>
      </geometry>
    </collision>
  </link>
  <link name="right_crank">
    <inertial>
      <origin rpy="0 0 0" xyz="-0.000200000000003065 0.0199435877845359 0.0292245259211331"/>
      <mass value="0.00853198276973456"/>
      <inertia ixx="2.89328108496468E-06" ixy="-1.57935047237397E-19" ixz="-1.93980378593255E-19" iyy="1.86719750325683E-06" iyz="-1.21858577871576E-06" izz="1.21905238907251E-06"/>
    </inertial>
    <visual>
      <origin rpy="0 0 0" xyz="0 0 0"/>
      <geometry>
        <mesh filename="../meshes/ag95/link_crank.STL" scale="1 1 1"/>
      </geometry>
      <material name="">
        <color rgba="0.1 0.1 0.1 1"/>
      </material>
    </visual>
    <collision>
      <origin rpy="0 0 0" xyz="0 0 0"/>
      <geometry>
        <mesh filename="../meshes/ag95/link_crank.STL" scale="1 1 1"/>
      </geometry>
    </collision>
  </link>
  <link name="right_rod">
    <inertial>
      <origin rpy="0 0 0" xyz="0.00030115855001899 0.0373907951953854 -0.0208027427000385"/>
      <mass value="0.022614240507152"/>
      <inertia ixx="1.52518312458174E-05" ixy="9.76583423954399E-10" ixz="-5.43838577022588E-10" iyy="6.17694243867776E-06" iyz="6.78636130740228E-06" izz="1.16494917907219E-05"/>
    </inertial>
    <visual>
      <origin rpy="0 0 0" xyz="0 0 0"/>
      <geometry>
        <mesh filename="../meshes/ag95/link_rod.STL" scale="1 1 1"/>
      </geometry>
      <material name="">
        <color rgba="0.1 0.1 0.1 1"/>
      </material>
    </visual>
    <collision>
      <origin rpy="0 0 0" xyz="0 0 0"/>
      <geometry>
        <mesh filename="../meshes/ag95/link_rod.STL" scale="1 1 1"/>
      </geometry>
    </collision>
  </link>
  <link name="right_distal_phalanx">
    <inertial>
      <origin rpy="0 0 0" xyz="0.000299999999999317 0.0160078233491243 -0.0136945669206257"/>
      <mass value="0.0104003125914103"/>
      <inertia ixx="2.71909453810972E-06" ixy="1.35402465472579E-21" ixz="-7.1817349065269E-22" iyy="7.69100314106116E-07" iyz="6.74715432769696E-07" izz="2.30315190420171E-06"/>
    </inertial>
    <visual>
      <origin rpy="0 0 0" xyz="0 0 0"/>
      <geometry>
        <mesh filename="../meshes/ag95/link_distal_phalanx.STL" scale="1 1 1"/>
      </geometry>
      <material name="">
        <color rgba="0.792156862745098 0.819607843137255 0.933333333333333 1"/>
      </material>
    </visual>
    <collision>
      <origin rpy="0 0 0" xyz="0 0 0"/>
      <geometry>
        <mesh filename="../meshes/ag95/link_distal_phalanx.STL" scale="1 1 1"/>
      </geometry>
    </collision>
  </link>
  <link name="right_proximal_phalanx">
    <inertial>
      <origin rpy="0 0 0" xyz="0.000123011831763771 0.0507850843201817 0.00103968640075166"/>
      <mass value="0.0271177346495152"/>
      <inertia ixx="2.61910379223783E-05" ixy="-2.43616858946494E-07" ixz="-6.37789906117123E-09" iyy="2.8270243746167E-06" iyz="-5.37200748039765E-07" izz="2.83695868220296E-05"/>
    </inertial>
    <visual>
      <origin rpy="0 0 0" xyz="0 0 0"/>
      <geometry>
        <mesh filename="../meshes/ag95/link_proximal_phalanx.STL" scale="1 1 1"/>
      </geometry>
      <material name="">
        <color rgba="0.1 0.1 0.1 1"/>
      </material>
    </visual>
    <collision>
      <origin rpy="0 0 0" xyz="0 0 0"/>
      <geometry>
        <mesh filename="../meshes/ag95/link_proximal_phalanx.STL" scale="1 1 1"/>
      </geometry>
    </collision>
  </link>
  <joint name="finger_joint" type="revolute">
    <origin rpy="-0.6523  0 0 " xyz="0 0.016 0.10586 "/>
    <parent link="dh_robotics_ag95_base_link"/>
    <child link="left_crank"/>
    <axis xyz="1 0 0"/>
    <limit effort="1000" lower="0" upper="0.6524" velocity="1.0"/>
  </joint>
  <joint name="left_rod_joint" type="revolute">
    <origin rpy="0.29795 0 0" xyz="0 0.037 0"/>
    <parent link="left_crank"/>
    <child link="left_rod"/>
    <axis xyz="1 0 0"/>
    <limit effort="1000" lower="-1" upper="0" velocity="1.0"/>
    <mimic joint="finger_joint" multiplier="0.4563942" offset="0"/>
  </joint>
  <joint name="left_proximal_phalanx_joint" type="revolute">
    <origin rpy="-0.801 0 0.0" xyz="0 0.016 0.10586"/>
    --&gt;
      
    <parent link="dh_robotics_ag95_base_link"/>
    <child link="left_proximal_phalanx"/>
    <axis xyz="1 0 0"/>
    <limit effort="1000" lower="0" upper="0.8757" velocity="1.0"/>
    <mimic joint="finger_joint" multiplier="1.451855" offset="0"/>
  </joint>
  <joint name="left_distal_phalanx_joint" type="revolute">
    <origin rpy="0.0132645 0 0" xyz="0 0 0.06083"/>
    <parent link="left_rod"/>
    <child link="left_distal_phalanx"/>
    <axis xyz="1 0 0"/>
    <limit effort="1000" lower="-1" upper="0" velocity="1.0"/>
    <mimic joint="finger_joint" multiplier="-1.4563851" offset="0"/>
  </joint>
  <joint name="right_crank_joint" type="revolute">
    <origin rpy="-0.6523  0 3.141592653589793 " xyz="0 -0.016 0.10586 "/>
    <parent link="dh_robotics_ag95_base_link"/>
    <child link="right_crank"/>
    <axis xyz="1 0 0"/>
    <limit effort="1000" lower="0" upper="0.6524" velocity="1.0"/>
    <mimic joint="finger_joint" multiplier="1" offset="0"/>
  </joint>
  <joint name="right_rod_joint" type="revolute">
    <origin rpy="0.29795 0 0" xyz="0 0.037 0"/>
    <parent link="right_crank"/>
    <child link="right_rod"/>
    <axis xyz="1 0 0"/>
    <limit effort="1000" lower="-1" upper="0" velocity="1.0"/>
    <mimic joint="finger_joint" multiplier="0.4563942" offset="0"/>
  </joint>
  <joint name="right_proximal_phalanx_joint" type="revolute">
    <origin rpy="-0.801 0 3.141592653589793" xyz="0 -0.016 0.10586"/>
    --&gt;
      
    <parent link="dh_robotics_ag95_base_link"/>
    <child link="right_proximal_phalanx"/>
    <axis xyz="1 0 0"/>
    <limit effort="1000" lower="0" upper="0.8757" velocity="1.0"/>
    <mimic joint="finger_joint" multiplier="1.451855" offset="0"/>
  </joint>
  <joint name="right_distal_phalanx_joint" type="revolute">
    <origin rpy="0.0132645 0 0" xyz="0 0 0.06083"/>
    <parent link="right_rod"/>
    <child link="right_distal_phalanx"/>
    <axis xyz="1 0 0"/>
    <limit effort="1000" lower="-1" upper="0" velocity="1.0"/>
    <mimic joint="finger_joint" multiplier="-1.4563851" offset="0"/>
  </joint>
  <transmission name="finger_joint_trans">
    <type>transmission_interface/SimpleTransmission</type>
    <joint name="finger_joint">
      <hardwareInterface>PositionJointInterface</hardwareInterface>
    </joint>
    <actuator name="finger_joint_motor">
      <mechanicalReduction>1</mechanicalReduction>
    </actuator>
  </transmission>
</robot>

