<?xml version="1.0" ?>
<!-- =================================================================================== -->
<!-- |    This document was autogenerated by xacro from /home/tzt/agilex_ws/agilex_ws/src/moveit_config/ranger_mini_cr5/ranger_mini_cr5_description/urdf/ranger_mini_cr5_with_gripper.xacro | -->
<!-- |    EDITING THIS FILE BY HAND IS NOT RECOMMENDED                                 | -->
<!-- =================================================================================== -->
<robot name="ranger_mini_box">
  <link name="base_link">
    <inertial>
      <origin rpy="0 0 0" xyz="-0.0242698272228022 -0.0030308024613212 0.0544267444673498"/>
      <mass value="24"/>
      <inertia ixx="0.1354" ixy="0.0" ixz="0.0" iyy="0.2417" iyz="0.0" izz="0.3085"/>
    </inertial>
    <visual>
      <origin rpy="0 0 0" xyz="0 0 0.0"/>
      <geometry>
        <mesh filename="../meshes/ranger_mini/ranger_base.dae" scale="1000 1000 1000"/>
      </geometry>
      <material name="">
        <color rgba="0.792156862745098 0.819607843137255 0.933333333333333 1"/>
      </material>
    </visual>
    <collision>
      <origin rpy="0 0 0" xyz="0 0 -0.1"/>
      <geometry>
        <box size="0.5 0.35 0.2"/>
      </geometry>
    </collision>
  </link>
  <link name="fr_steering_wheel_link">
    <inertial>
      <origin rpy="0 0 0" xyz="1.8493E-05 1.2713E-06 0.043679"/>
      <mass value="1"/>
      <inertia ixx="0.0063625" ixy="-1.0581E-07" ixz="-4.0831E-07" iyy="0.006363" iyz="-3.4944E-08" izz="0.010465"/>
    </inertial>
    <visual>
      <origin rpy="0 0 0" xyz="0 0 0"/>
      <geometry>
        <mesh filename="../meshes/ranger_mini/steering_wheel.dae" scale="10 10 10"/>
      </geometry>
      <material name="">
        <color rgba="0.79216 0.81961 0.93333 1"/>
      </material>
    </visual>
    <collision>
      <origin rpy="0 0 0" xyz="0 0 0"/>
      <geometry>
        <!-- <mesh
          filename="../meshes/ranger_mini/ranger_mini_v3_wheel_right.dae" /> -->
        <cylinder length="0.01" radius="0.01"/>
      </geometry>
    </collision>
  </link>
  <joint name="fr_steering_joint" type="revolute">
    <origin rpy="0 0 0" xyz="0.25 -0.19 -0.1"/>
    <parent link="base_link"/>
    <child link="fr_steering_wheel_link"/>
    <axis xyz="0 0 -1"/>
    <limit effort="5" lower="-2.1" upper="2.1" velocity="6.28"/>
  </joint>
  <link name="fr_wheel_link">
    <inertial>
      <mass value="8"/>
      <origin xyz="0 0 0"/>
      <inertia ixx="0.02047" ixy="0.0" ixz="0.0" iyy="0.02047" iyz="0.0" izz="0.0324"/>
    </inertial>
    <visual>
      <origin rpy="3.14 0 0" xyz="0 0 0"/>
      <geometry>
        <mesh filename="../meshes/ranger_mini/wheel_v3.dae" scale="10 10 10"/>
      </geometry>
    </visual>
    <collision>
      <origin rpy="1.57 0 0" xyz="0 0 -0.005"/>
      <geometry>
        <cylinder length="0.08" radius="0.09"/>
      </geometry>
      <contact>
        <ode>
          <min_depth>0.005</min_depth>
        </ode>
      </contact>
    </collision>
  </link>
  <joint name="fr_wheel" type="continuous">
    <origin rpy="0 0 0" xyz="0.0 0.0 -0.12"/>
    <parent link="fr_steering_wheel_link"/>
    <child link="fr_wheel_link"/>
    <axis rpy="0 0 0" xyz="0 1 0"/>
  </joint>
  <link name="fl_steering_wheel_link">
    <inertial>
      <origin rpy="0 0 0" xyz="-0.0017956 -9.6304E-08 0.043642"/>
      <mass value="1"/>
      <inertia ixx="0.0063695" ixy="-2.1067E-08" ixz="-0.00016867" iyy="0.006363" iyz="-1.0301E-08" izz="0.010458"/>
    </inertial>
    <visual>
      <origin rpy="0 0 3.14" xyz="0 0 0"/>
      <geometry>
        <mesh filename="../meshes/ranger_mini/steering_wheel.dae" scale="10 10 10"/>
      </geometry>
      <material name="">
        <color rgba="0.79216 0.81961 0.93333 1"/>
      </material>
    </visual>
    <collision>
      <origin rpy="0 0 0" xyz="0 0 0"/>
      <geometry>
        <!-- <mesh
          filename="../meshes/ranger_mini/ranger_mini_v3_wheel.dae" /> -->
        <cylinder length="0.01" radius="0.01"/>
      </geometry>
    </collision>
  </link>
  <joint name="fl_steering_joint" type="revolute">
    <origin rpy="0 0 0" xyz="0.25 0.19 -0.1"/>
    <parent link="base_link"/>
    <child link="fl_steering_wheel_link"/>
    <axis xyz="0 0 -1"/>
    <limit effort="5" lower="-2.1" upper="2.1" velocity="6.28"/>
  </joint>
  <link name="fl_wheel_link">
    <inertial>
      <mass value="8"/>
      <origin xyz="0 0 0"/>
      <inertia ixx="0.02047" ixy="0.0" ixz="0.0" iyy="0.02047" iyz="0.0" izz="0.0324"/>
    </inertial>
    <visual>
      <origin rpy="0 0 0" xyz="0 0 0"/>
      <geometry>
        <mesh filename="../meshes/ranger_mini/wheel_v3.dae" scale="10 10 10"/>
      </geometry>
    </visual>
    <collision>
      <origin rpy="1.57 0 0" xyz="0 0 -0.005"/>
      <geometry>
        <cylinder length="0.08" radius="0.09"/>
      </geometry>
      <contact>
        <ode>
          <min_depth>0.005</min_depth>
        </ode>
      </contact>
    </collision>
  </link>
  <joint name="fl_wheel" type="continuous">
    <origin rpy="0 0 0" xyz="0.0 0.0 -0.12"/>
    <parent link="fl_steering_wheel_link"/>
    <child link="fl_wheel_link"/>
    <axis rpy="0 0 0" xyz="0 1 0"/>
  </joint>
  <link name="rl_steering_wheel_link">
    <inertial>
      <origin rpy="0 0 0" xyz="-0.00017093 6.1255E-08 0.043678"/>
      <mass value="1"/>
      <inertia ixx="0.0063627" ixy="-2.1069E-08" ixz="-1.587E-05" iyy="0.006363" iyz="9.3201E-09" izz="0.010465"/>
    </inertial>
    <visual>
      <origin rpy="0 0 3.14" xyz="0 0 0"/>
      <geometry>
        <mesh filename="../meshes/ranger_mini/steering_wheel.dae" scale="10 10 10"/>
      </geometry>
      <material name="">
        <color rgba="0.79216 0.81961 0.93333 1"/>
      </material>
    </visual>
    <collision>
      <origin rpy="0 0 0" xyz="0 0 0"/>
      <geometry>
        <!-- <mesh
          filename="../meshes/ranger_mini/ranger_mini_v3_wheel_right.dae" /> -->
        <cylinder length="0.01" radius="0.01"/>
      </geometry>
    </collision>
  </link>
  <joint name="rl_steering_joint" type="revolute">
    <origin rpy="0 0 0" xyz="-0.25 0.19 -0.1"/>
    <parent link="base_link"/>
    <child link="rl_steering_wheel_link"/>
    <axis xyz="0 0 -1"/>
    <limit effort="5" lower="-2.1" upper="2.1" velocity="6.28"/>
  </joint>
  <link name="rl_wheel_link">
    <inertial>
      <mass value="8"/>
      <origin xyz="0 0 0"/>
      <inertia ixx="0.02047" ixy="0.0" ixz="0.0" iyy="0.02047" iyz="0.0" izz="0.0324"/>
    </inertial>
    <visual>
      <origin rpy="0 0 0" xyz="0 0 0"/>
      <geometry>
        <mesh filename="../meshes/ranger_mini/wheel_v3.dae" scale="10 10 10"/>
      </geometry>
    </visual>
    <collision>
      <origin rpy="1.57 0 0" xyz="0.00 0.00 -0.005"/>
      <geometry>
        <cylinder length="0.08" radius="0.09"/>
      </geometry>
      <contact>
        <ode>
          <min_depth>0.005</min_depth>
        </ode>
      </contact>
    </collision>
  </link>
  <joint name="rl_wheel" type="continuous">
    <origin rpy="0 0 0" xyz="0.0 0.0 -0.12 "/>
    <parent link="rl_steering_wheel_link"/>
    <child link="rl_wheel_link"/>
    <axis rpy="0 0 0" xyz="0 1 0"/>
  </joint>
  <link name="rr_steering_wheel_link">
    <inertial>
      <origin xyz="0.0 0.0 0.0"/>
      <mass value="1"/>
      <inertia ixx="0.01" ixy="0.0" ixz="0.0" iyy="0.01" iyz="0.0" izz="0.01"/>
    </inertial>
    <visual>
      <origin rpy="0 0 0" xyz="0 0 0"/>
      <geometry>
        <mesh filename="../meshes/ranger_mini/steering_wheel.dae" scale="10 10 10"/>
      </geometry>
    </visual>
    <collision>
      <origin rpy="0 0 0" xyz="0 0 0"/>
      <geometry>
        <cylinder length="0.01" radius="0.01"/>
      </geometry>
    </collision>
  </link>
  <joint name="rr_steering_joint" type="revolute">
    <origin rpy="0 0 0" xyz="-0.23 -0.206 -0.1"/>
    <parent link="base_link"/>
    <child link="rr_steering_wheel_link"/>
    <axis rpy="0 0 0" xyz="0 0 -1"/>
    <limit effort="5" lower="-2.1" upper="2.1" velocity="6.28"/>
  </joint>
  <link name="rr_wheel_link">
    <inertial>
      <mass value="8"/>
      <origin xyz="0 0 0"/>
      <inertia ixx="0.02047" ixy="0.0" ixz="0.0" iyy="0.02047" iyz="0.0" izz="0.0324"/>
    </inertial>
    <visual>
      <origin rpy="3.14 0 0" xyz="0.0 0.0 0.0"/>
      <geometry>
        <mesh filename="../meshes/ranger_mini/wheel_v3.dae" scale="10 10 10"/>
      </geometry>
    </visual>
    <collision>
      <origin rpy="1.57 0 0" xyz="0.0 0.0 -0.005"/>
      <geometry>
        <cylinder length="0.08" radius="0.09"/>
      </geometry>
      <contact>
        <ode>
          <min_depth>0.005</min_depth>
        </ode>
      </contact>
    </collision>
  </link>
  <joint name="rr_wheel" type="continuous">
    <origin rpy="0 0 0" xyz="0.0 0.0 -0.12 "/>
    <parent link="rr_steering_wheel_link"/>
    <child link="rr_wheel_link"/>
    <axis rpy="0 0 0" xyz="0 1 0"/>
  </joint>
  <!-- 
	<transmission name="fl_steering_wheel_trans">
      <type>transmission_interface/SimpleTransmission</type>
      <joint name="fl_steering_joint">
		<hardwareInterface>hardware_interface/PositionJointInterface</hardwareInterface>
      </joint>
	  <actuator name="fl_steering_wheel_motor">
		<hardwareInterface>hardware_interface/PositionJointInterface</hardwareInterface>
		<mechanicalReduction>30</mechanicalReduction>
      </actuator>
	</transmission>

	<transmission name="fr_steering_wheel_trans">
      <type>transmission_interface/SimpleTransmission</type>
      <joint name="fr_steering_joint">
		<hardwareInterface>hardware_interface/PositionJointInterface</hardwareInterface>
      </joint>
	  <actuator name="fr_steering_wheel_motor">
		<hardwareInterface>hardware_interface/PositionJointInterface</hardwareInterface>
		<mechanicalReduction>30</mechanicalReduction>
      </actuator>
	</transmission>

	<transmission name="rl_steering_wheel_trans">
      <type>transmission_interface/SimpleTransmission</type>
      <joint name="rl_steering_joint">
		<hardwareInterface>hardware_interface/PositionJointInterface</hardwareInterface>
      </joint>
	  <actuator name="rl_steering_wheel_motor">
		<hardwareInterface>hardware_interface/PositionJointInterface</hardwareInterface>
		<mechanicalReduction>30</mechanicalReduction>
      </actuator>
	</transmission>

	<transmission name="rr_steering_wheel_trans">
      <type>transmission_interface/SimpleTransmission</type>
      <joint name="rr_steering_joint">
		<hardwareInterface>hardware_interface/PositionJointInterface</hardwareInterface>
      </joint>
	  <actuator name="rr_steering_wheel_motor">
		<hardwareInterface>hardware_interface/PositionJointInterface</hardwareInterface>
		<mechanicalReduction>30</mechanicalReduction>
      </actuator>
	</transmission>

	<transmission name="fl_wheel_trans">
      <type>transmission_interface/SimpleTransmission</type>
      <joint name="fl_wheel">
		<hardwareInterface>hardware_interface/VelocityJointInterface</hardwareInterface>
      </joint>
	  <actuator name="fl_wheel_motor">
		<hardwareInterface>hardware_interface/VelocityJointInterface</hardwareInterface>
		<mechanicalReduction>30</mechanicalReduction>
      </actuator>
	</transmission>

	<transmission name="fr_wheel_trans">
      <type>transmission_interface/SimpleTransmission</type>
      <joint name="fr_wheel">
		<hardwareInterface>hardware_interface/VelocityJointInterface</hardwareInterface>
      </joint>
	  <actuator name="fr_wheel_motor">
		<hardwareInterface>hardware_interface/VelocityJointInterface</hardwareInterface>
		<mechanicalReduction>30</mechanicalReduction>
      </actuator>
	</transmission>

	<transmission name="rl_wheel_trans">
      <type>transmission_interface/SimpleTransmission</type>
      <joint name="rl_wheel">
		<hardwareInterface>hardware_interface/VelocityJointInterface</hardwareInterface>
      </joint>
	  <actuator name="rl_wheel_motor">
		<hardwareInterface>hardware_interface/VelocityJointInterface</hardwareInterface>
		<mechanicalReduction>30</mechanicalReduction>
      </actuator>
	</transmission>

	<transmission name="rr_wheel_trans">
      <type>transmission_interface/SimpleTransmission</type>
      <joint name="rr_wheel">
		<hardwareInterface>hardware_interface/VelocityJointInterface</hardwareInterface>
      </joint>
	  <actuator name="rr_wheel_motor">
		<hardwareInterface>hardware_interface/VelocityJointInterface</hardwareInterface>
		<mechanicalReduction>30</mechanicalReduction>
      </actuator>
	</transmission>
  <gazebo>
    <plugin name="gazebo_ros_control" filename="libgazebo_ros_control.so">
    </plugin>
  </gazebo> -->
  <link name="arm_base">
    <inertial>
      <origin rpy="0 0 0" xyz="-8.0961E-06 0.0019103 0.028995"/>
      <mass value="0.90882"/>
      <inertia ixx="0.0014545" ixy="4.2968E-08" ixz="-1.8199E-07" iyy="0.001345" iyz="-6.243E-06" izz="0.002155"/>
    </inertial>
    <visual>
      <origin rpy="0 0 0" xyz="0 0 0"/>
      <geometry>
        <mesh filename="../meshes/cr5/base_link.dae"/>
      </geometry>
      <material name="">
        <color rgba="0 0 0 1"/>
      </material>
    </visual>
    <collision>
      <origin rpy="0 0 0" xyz="0 0 0"/>
      <geometry>
        <mesh filename="../meshes/cr5/base_link.dae"/>
      </geometry>
    </collision>
  </link>
  <link name="Link1">
    <inertial>
      <origin rpy="0 0 0" xyz="-8.7268E-07 -0.0032576 -0.0076748"/>
      <mass value="1.6123"/>
      <inertia ixx="0.0029122" ixy="5.7387E-09" ixz="1.9945E-08" iyy="0.0028191" iyz="0.00044094" izz="0.0032836"/>
    </inertial>
    <visual>
      <origin rpy="0 0 0" xyz="0 0 0"/>
      <geometry>
        <mesh filename="../meshes/cr5/Link1.dae"/>
      </geometry>
      <material name="">
        <color rgba="1 1 1 1"/>
      </material>
    </visual>
    <collision>
      <origin rpy="0 0 0" xyz="0 0 0"/>
      <geometry>
        <mesh filename="../meshes/cr5/Link1.dae"/>
      </geometry>
    </collision>
  </link>
  <joint name="joint1" type="revolute">
    <origin rpy="0 0 0" xyz="0 0 0.147"/>
    <parent link="arm_base"/>
    <child link="Link1"/>
    <axis xyz="0 0 1"/>
    <limit effort="0" lower="-3.14" upper="3.14" velocity="0"/>
  </joint>
  <link name="Link2">
    <inertial>
      <origin rpy="0 0 0" xyz="-0.21351 -1.3842E-06 0.14252"/>
      <mass value="5.5186"/>
      <inertia ixx="0.0085919" ixy="7.5552E-07" ixz="-7.8922E-07" iyy="0.027553" iyz="1.4629E-07" izz="0.028294"/>
    </inertial>
    <visual>
      <origin rpy="0 0 0" xyz="0 0 0"/>
      <geometry>
        <mesh filename="../meshes/cr5/Link2.dae"/>
      </geometry>
      <material name="">
        <color rgba="1 1 1 1"/>
      </material>
    </visual>
    <collision>
      <origin rpy="0 0 0" xyz="0 0 0"/>
      <geometry>
        <mesh filename="../meshes/cr5/Link2.dae"/>
      </geometry>
    </collision>
  </link>
  <joint name="joint2" type="revolute">
    <origin rpy="1.5708 1.5708 0" xyz="0 0 0"/>
    <parent link="Link1"/>
    <child link="Link2"/>
    <axis xyz="0 0 1"/>
    <limit effort="0" lower="-3.14" upper="3.14" velocity="0"/>
  </joint>
  <link name="Link3">
    <inertial>
      <origin rpy="0 0 0" xyz="-0.15231 -1.4079E-07 0.022693"/>
      <mass value="2.8536"/>
      <inertia ixx="0.0032608" ixy="-3.2147E-10" ixz="0.00012363" iyy="0.0092967" iyz="2.9478E-10" izz="0.0095552"/>
    </inertial>
    <visual>
      <origin rpy="0 0 0" xyz="0 0 0"/>
      <geometry>
        <mesh filename="../meshes/cr5/Link3.dae"/>
      </geometry>
      <material name="">
        <color rgba="1 1 1 1"/>
      </material>
    </visual>
    <collision>
      <origin rpy="0 0 0" xyz="0 0 0"/>
      <geometry>
        <mesh filename="../meshes/cr5/Link3.dae"/>
      </geometry>
    </collision>
  </link>
  <joint name="joint3" type="revolute">
    <origin rpy="0 0 0" xyz="-0.427 0 0"/>
    <parent link="Link2"/>
    <child link="Link3"/>
    <axis xyz="0 0 1"/>
    <limit effort="0" lower="-2.86" upper="2.86" velocity="0"/>
  </joint>
  <link name="Link4">
    <inertial>
      <origin rpy="0 0 0" xyz="-3.2386E-07 -0.002077 -0.0015548"/>
      <mass value="0.67058"/>
      <inertia ixx="0.00066939" ixy="4.1975E-10" ixz="-1.0734E-08" iyy="0.00065424" iyz="0.00011081" izz="0.00065365"/>
    </inertial>
    <visual>
      <origin rpy="0 0 0" xyz="0 0 0"/>
      <geometry>
        <mesh filename="../meshes/cr5/Link4.dae"/>
      </geometry>
      <material name="">
        <color rgba="1 1 1 1"/>
      </material>
    </visual>
    <collision>
      <origin rpy="0 0 0" xyz="0 0 0"/>
      <geometry>
        <mesh filename="../meshes/cr5/Link4.dae"/>
      </geometry>
    </collision>
  </link>
  <joint name="joint4" type="revolute">
    <origin rpy="0 0 -1.5708" xyz="-0.357 0 0.141"/>
    <parent link="Link3"/>
    <child link="Link4"/>
    <axis xyz="0 0 1"/>
    <limit effort="0" lower="-3.14" upper="3.14" velocity="0"/>
  </joint>
  <link name="Link5">
    <inertial>
      <origin rpy="0 0 0" xyz="-3.7738E-07 -0.0045777 -0.0012971"/>
      <mass value="0.7269"/>
      <inertia ixx="0.00073069" ixy="-5.7806E-09" ixz="6.7132E-09" iyy="0.00071195" iyz="-0.00011926" izz="0.00071391"/>
    </inertial>
    <visual>
      <origin rpy="0 0 0" xyz="0 0 0"/>
      <geometry>
        <mesh filename="../meshes/cr5/Link5.dae"/>
      </geometry>
      <material name="">
        <color rgba="1 1 1 1"/>
      </material>
    </visual>
    <collision>
      <origin rpy="0 0 0" xyz="0 0 0"/>
      <geometry>
        <mesh filename="../meshes/cr5/Link5.dae"/>
      </geometry>
    </collision>
  </link>
  <joint name="joint5" type="revolute">
    <origin rpy="1.5708 0 0" xyz="0 -0.116 0"/>
    <parent link="Link4"/>
    <child link="Link5"/>
    <axis xyz="0 0 1"/>
    <limit effort="0" lower="-3.14" upper="3.14" velocity="0"/>
  </joint>
  <link name="Link6">
    <inertial>
      <origin rpy="0 0 0" xyz="5.0777E-11 9.3774E-05 -0.019285"/>
      <mass value="0.15789"/>
      <inertia ixx="7.8045E-05" ixy="6.1582E-15" ixz="6.2471E-14" iyy="7.9168E-05" iyz="-1.3822E-07" izz="0.00012951"/>
    </inertial>
    <visual>
      <origin rpy="0 0 0" xyz="0 0 0"/>
      <geometry>
        <mesh filename="../meshes/cr5/Link6.dae"/>
      </geometry>
      <material name="">
        <color rgba="1 1 1 1"/>
      </material>
    </visual>
    <collision>
      <origin rpy="0 0 0" xyz="0 0 0"/>
      <geometry>
        <mesh filename="../meshes/cr5/Link6.dae"/>
      </geometry>
    </collision>
  </link>
  <joint name="joint6" type="revolute">
    <origin rpy="-1.5708 0 0" xyz="0 0.105 0"/>
    <parent link="Link5"/>
    <child link="Link6"/>
    <axis xyz="0 0 1"/>
    <limit effort="0" lower="-6.28" upper="6.28" velocity="0"/>
  </joint>
  <link name="dh_robotics_ag95_base_link">
    <inertial>
      <origin rpy="0 0 0" xyz="0 0 0"/>
      <mass value="0.22652"/>
      <inertia ixx="0.00020005" ixy="-4.2442E-10" ixz="-2.9069E-10" iyy="0.00017832" iyz="-3.4402E-08" izz="0.00013478"/>
    </inertial>
    <visual>
      <origin rpy="0 0 0" xyz="0 0 0"/>
      <geometry>
        <mesh filename="../meshes/ag95/base_link.STL" scale="1 1 1"/>
      </geometry>
      <material name="">
        <color rgba="0.1 0.1 0.1 1"/>
      </material>
    </visual>
    <collision>
      <origin rpy="0 0 0" xyz="0 0 0"/>
      <geometry>
        <mesh filename="../meshes/ag95/base_link.STL"/>
      </geometry>
    </collision>
  </link>
  <link name="left_crank">
    <inertial>
      <origin rpy="0 0 0" xyz="-0.000200000000003065 0.0199435877845359 0.0292245259211331"/>
      <mass value="0.00853198276973456"/>
      <inertia ixx="2.89328108496468E-06" ixy="-1.57935047237397E-19" ixz="-1.93980378593255E-19" iyy="1.86719750325683E-06" iyz="-1.21858577871576E-06" izz="1.21905238907251E-06"/>
    </inertial>
    <visual>
      <origin rpy="0 0 0" xyz="0 0 0"/>
      <geometry>
        <mesh filename="../meshes/ag95/link_crank.STL" scale="1 1 1"/>
      </geometry>
      <material name="">
        <color rgba="0.1 0.1 0.1 1"/>
      </material>
    </visual>
    <collision>
      <origin rpy="0 0 0" xyz="0 0 0"/>
      <geometry>
        <mesh filename="../meshes/ag95/link_crank.STL" scale="1 1 1"/>
      </geometry>
    </collision>
  </link>
  <link name="left_rod">
    <inertial>
      <origin rpy="0 0 0" xyz="0.00030115855001899 0.0373907951953854 -0.0208027427000385"/>
      <mass value="0.022614240507152"/>
      <inertia ixx="1.52518312458174E-05" ixy="9.76583423954399E-10" ixz="-5.43838577022588E-10" iyy="6.17694243867776E-06" iyz="6.78636130740228E-06" izz="1.16494917907219E-05"/>
    </inertial>
    <visual>
      <origin rpy="0 0 0" xyz="0 0 0"/>
      <geometry>
        <mesh filename="../meshes/ag95/link_rod.STL" scale="1 1 1"/>
      </geometry>
      <material name="">
        <color rgba="0.1 0.1 0.1 1"/>
      </material>
    </visual>
    <collision>
      <origin rpy="0 0 0" xyz="0 0 0"/>
      <geometry>
        <mesh filename="../meshes/ag95/link_rod.STL" scale="1 1 1"/>
      </geometry>
    </collision>
  </link>
  <link name="left_distal_phalanx">
    <inertial>
      <origin rpy="0 0 0" xyz="0.000299999999999317 0.0160078233491243 -0.0136945669206257"/>
      <mass value="0.0104003125914103"/>
      <inertia ixx="2.71909453810972E-06" ixy="1.35402465472579E-21" ixz="-7.1817349065269E-22" iyy="7.69100314106116E-07" iyz="6.74715432769696E-07" izz="2.30315190420171E-06"/>
    </inertial>
    <visual>
      <origin rpy="0 0 0" xyz="0 0 0"/>
      <geometry>
        <mesh filename="../meshes/ag95/link_distal_phalanx.STL" scale="1 1 1"/>
      </geometry>
      <material name="">
        <color rgba="0.792156862745098 0.819607843137255 0.933333333333333 1"/>
      </material>
    </visual>
    <collision>
      <origin rpy="0 0 0" xyz="0 0 0"/>
      <geometry>
        <mesh filename="../meshes/ag95/link_distal_phalanx.STL" scale="1 1 1"/>
      </geometry>
    </collision>
  </link>
  <link name="left_proximal_phalanx">
    <inertial>
      <origin rpy="0 0 0" xyz="0.000123011831763771 0.0507850843201817 0.00103968640075166"/>
      <mass value="0.0271177346495152"/>
      <inertia ixx="2.61910379223783E-05" ixy="-2.43616858946494E-07" ixz="-6.37789906117123E-09" iyy="2.8270243746167E-06" iyz="-5.37200748039765E-07" izz="2.83695868220296E-05"/>
    </inertial>
    <visual>
      <origin rpy="0 0 0" xyz="0 0 0"/>
      <geometry>
        <mesh filename="../meshes/ag95/link_proximal_phalanx.STL" scale="1 1 1"/>
      </geometry>
      <material name="">
        <color rgba="0.1 0.1 0.1 1"/>
      </material>
    </visual>
    <collision>
      <origin rpy="0 0 0" xyz="0 0 0"/>
      <geometry>
        <mesh filename="../meshes/ag95/link_proximal_phalanx.STL" scale="1 1 1"/>
      </geometry>
    </collision>
  </link>
  <link name="right_crank">
    <inertial>
      <origin rpy="0 0 0" xyz="-0.000200000000003065 0.0199435877845359 0.0292245259211331"/>
      <mass value="0.00853198276973456"/>
      <inertia ixx="2.89328108496468E-06" ixy="-1.57935047237397E-19" ixz="-1.93980378593255E-19" iyy="1.86719750325683E-06" iyz="-1.21858577871576E-06" izz="1.21905238907251E-06"/>
    </inertial>
    <visual>
      <origin rpy="0 0 0" xyz="0 0 0"/>
      <geometry>
        <mesh filename="../meshes/ag95/link_crank.STL" scale="1 1 1"/>
      </geometry>
      <material name="">
        <color rgba="0.1 0.1 0.1 1"/>
      </material>
    </visual>
    <collision>
      <origin rpy="0 0 0" xyz="0 0 0"/>
      <geometry>
        <mesh filename="../meshes/ag95/link_crank.STL" scale="1 1 1"/>
      </geometry>
    </collision>
  </link>
  <link name="right_rod">
    <inertial>
      <origin rpy="0 0 0" xyz="0.00030115855001899 0.0373907951953854 -0.0208027427000385"/>
      <mass value="0.022614240507152"/>
      <inertia ixx="1.52518312458174E-05" ixy="9.76583423954399E-10" ixz="-5.43838577022588E-10" iyy="6.17694243867776E-06" iyz="6.78636130740228E-06" izz="1.16494917907219E-05"/>
    </inertial>
    <visual>
      <origin rpy="0 0 0" xyz="0 0 0"/>
      <geometry>
        <mesh filename="../meshes/ag95/link_rod.STL" scale="1 1 1"/>
      </geometry>
      <material name="">
        <color rgba="0.1 0.1 0.1 1"/>
      </material>
    </visual>
    <collision>
      <origin rpy="0 0 0" xyz="0 0 0"/>
      <geometry>
        <mesh filename="../meshes/ag95/link_rod.STL" scale="1 1 1"/>
      </geometry>
    </collision>
  </link>
  <link name="right_distal_phalanx">
    <inertial>
      <origin rpy="0 0 0" xyz="0.000299999999999317 0.0160078233491243 -0.0136945669206257"/>
      <mass value="0.0104003125914103"/>
      <inertia ixx="2.71909453810972E-06" ixy="1.35402465472579E-21" ixz="-7.1817349065269E-22" iyy="7.69100314106116E-07" iyz="6.74715432769696E-07" izz="2.30315190420171E-06"/>
    </inertial>
    <visual>
      <origin rpy="0 0 0" xyz="0 0 0"/>
      <geometry>
        <mesh filename="../meshes/ag95/link_distal_phalanx.STL" scale="1 1 1"/>
      </geometry>
      <material name="">
        <color rgba="0.792156862745098 0.819607843137255 0.933333333333333 1"/>
      </material>
    </visual>
    <collision>
      <origin rpy="0 0 0" xyz="0 0 0"/>
      <geometry>
        <mesh filename="../meshes/ag95/link_distal_phalanx.STL" scale="1 1 1"/>
      </geometry>
    </collision>
  </link>
  <link name="right_proximal_phalanx">
    <inertial>
      <origin rpy="0 0 0" xyz="0.000123011831763771 0.0507850843201817 0.00103968640075166"/>
      <mass value="0.0271177346495152"/>
      <inertia ixx="2.61910379223783E-05" ixy="-2.43616858946494E-07" ixz="-6.37789906117123E-09" iyy="2.8270243746167E-06" iyz="-5.37200748039765E-07" izz="2.83695868220296E-05"/>
    </inertial>
    <visual>
      <origin rpy="0 0 0" xyz="0 0 0"/>
      <geometry>
        <mesh filename="../meshes/ag95/link_proximal_phalanx.STL" scale="1 1 1"/>
      </geometry>
      <material name="">
        <color rgba="0.1 0.1 0.1 1"/>
      </material>
    </visual>
    <collision>
      <origin rpy="0 0 0" xyz="0 0 0"/>
      <geometry>
        <mesh filename="../meshes/ag95/link_proximal_phalanx.STL" scale="1 1 1"/>
      </geometry>
    </collision>
  </link>
  <joint name="finger_joint" type="revolute">
    <origin rpy="-0.6523  0 0 " xyz="0 0.016 0.10586 "/>
    <parent link="dh_robotics_ag95_base_link"/>
    <child link="left_crank"/>
    <axis xyz="1 0 0"/>
    <limit effort="1000" lower="0" upper="0.6524" velocity="1.0"/>
  </joint>
  <joint name="left_rod_joint" type="revolute">
    <origin rpy="0.29795 0 0" xyz="0 0.037 0"/>
    <parent link="left_crank"/>
    <child link="left_rod"/>
    <axis xyz="1 0 0"/>
    <limit effort="1000" lower="-1" upper="0" velocity="1.0"/>
    <mimic joint="finger_joint" multiplier="0.4563942" offset="0"/>
  </joint>
  <joint name="left_proximal_phalanx_joint" type="revolute">
    <origin rpy="-0.801 0 0.0" xyz="0 0.016 0.10586"/>
    --&gt;
      
    <parent link="dh_robotics_ag95_base_link"/>
    <child link="left_proximal_phalanx"/>
    <axis xyz="1 0 0"/>
    <limit effort="1000" lower="0" upper="0.8757" velocity="1.0"/>
    <mimic joint="finger_joint" multiplier="1.451855" offset="0"/>
  </joint>
  <joint name="left_distal_phalanx_joint" type="revolute">
    <origin rpy="0.0132645 0 0" xyz="0 0 0.06083"/>
    <parent link="left_rod"/>
    <child link="left_distal_phalanx"/>
    <axis xyz="1 0 0"/>
    <limit effort="1000" lower="-1" upper="0" velocity="1.0"/>
    <mimic joint="finger_joint" multiplier="-1.4563851" offset="0"/>
  </joint>
  <joint name="right_crank_joint" type="revolute">
    <origin rpy="-0.6523  0 3.141592653589793 " xyz="0 -0.016 0.10586 "/>
    <parent link="dh_robotics_ag95_base_link"/>
    <child link="right_crank"/>
    <axis xyz="1 0 0"/>
    <limit effort="1000" lower="0" upper="0.6524" velocity="1.0"/>
    <mimic joint="finger_joint" multiplier="1" offset="0"/>
  </joint>
  <joint name="right_rod_joint" type="revolute">
    <origin rpy="0.29795 0 0" xyz="0 0.037 0"/>
    <parent link="right_crank"/>
    <child link="right_rod"/>
    <axis xyz="1 0 0"/>
    <limit effort="1000" lower="-1" upper="0" velocity="1.0"/>
    <mimic joint="finger_joint" multiplier="0.4563942" offset="0"/>
  </joint>
  <joint name="right_proximal_phalanx_joint" type="revolute">
    <origin rpy="-0.801 0 3.141592653589793" xyz="0 -0.016 0.10586"/>
    --&gt;
      
    <parent link="dh_robotics_ag95_base_link"/>
    <child link="right_proximal_phalanx"/>
    <axis xyz="1 0 0"/>
    <limit effort="1000" lower="0" upper="0.8757" velocity="1.0"/>
    <mimic joint="finger_joint" multiplier="1.451855" offset="0"/>
  </joint>
  <joint name="right_distal_phalanx_joint" type="revolute">
    <origin rpy="0.0132645 0 0" xyz="0 0 0.06083"/>
    <parent link="right_rod"/>
    <child link="right_distal_phalanx"/>
    <axis xyz="1 0 0"/>
    <limit effort="1000" lower="-1" upper="0" velocity="1.0"/>
    <mimic joint="finger_joint" multiplier="-1.4563851" offset="0"/>
  </joint>
  <transmission name="finger_joint_trans">
    <type>transmission_interface/SimpleTransmission</type>
    <joint name="finger_joint">
      <hardwareInterface>PositionJointInterface</hardwareInterface>
    </joint>
    <actuator name="finger_joint_motor">
      <mechanicalReduction>1</mechanicalReduction>
    </actuator>
  </transmission>
  <material name="aluminum">
    <color rgba="0.5 0.5 0.5 1"/>
  </material>
  <material name="plastic">
    <color rgba="0.1 0.1 0.1 1"/>
  </material>
  <!-- camera body, with origin at bottom screw mount -->
  <joint name="camera_joint" type="fixed">
    <origin rpy="0.0 -1.5708 1.5708" xyz="0.0 -0.065 0.01"/>
    <parent link="Link6"/>
    <child link="camera_bottom_screw_frame"/>
  </joint>
  <link name="camera_bottom_screw_frame"/>
  <joint name="camera_link_joint" type="fixed">
    <origin rpy="0 0 0" xyz="0.010600000000000002 0.0175 0.0125"/>
    <parent link="camera_bottom_screw_frame"/>
    <child link="camera_link"/>
  </joint>
  <link name="camera_link">
    <visual>
      <!-- the mesh origin is at front plate in between the two infrared camera axes -->
      <origin rpy="1.5707963267948966 0 1.5707963267948966" xyz="0.0043 -0.0175 0"/>
      <geometry>
        <mesh filename="../meshes/realsense/d435.dae"/>
      </geometry>
    </visual>
    <collision>
      <origin rpy="0 0 0" xyz="0 -0.0175 0"/>
      <geometry>
        <box size="0.02505 0.09 0.025"/>
      </geometry>
    </collision>
    <inertial>
      <!-- The following are not reliable values, and should not be used for modeling -->
      <mass value="0.072"/>
      <origin xyz="0 0 0"/>
      <inertia ixx="0.003881243" ixy="0.0" ixz="0.0" iyy="0.000498940" iyz="0.0" izz="0.003879257"/>
    </inertial>
  </link>
  <!-- camera depth joints and links -->
  <joint name="camera_depth_joint" type="fixed">
    <origin rpy="0 0 0" xyz="0 0 0"/>
    <parent link="camera_link"/>
    <child link="camera_depth_frame"/>
  </joint>
  <link name="camera_depth_frame"/>
  <joint name="camera_depth_optical_joint" type="fixed">
    <origin rpy="-1.5707963267948966 0 -1.5707963267948966" xyz="0 0 0"/>
    <parent link="camera_depth_frame"/>
    <child link="camera_depth_optical_frame"/>
  </joint>
  <link name="camera_depth_optical_frame"/>
  <!-- camera left IR joints and links -->
  <joint name="camera_infra1_joint" type="fixed">
    <origin rpy="0 0 0" xyz="0 0.0 0"/>
    <parent link="camera_link"/>
    <child link="camera_infra1_frame"/>
  </joint>
  <link name="camera_infra1_frame"/>
  <joint name="camera_infra1_optical_joint" type="fixed">
    <origin rpy="-1.5707963267948966 0 -1.5707963267948966" xyz="0 0 0"/>
    <parent link="camera_infra1_frame"/>
    <child link="camera_infra1_optical_frame"/>
  </joint>
  <link name="camera_infra1_optical_frame"/>
  <!-- camera right IR joints and links -->
  <joint name="camera_infra2_joint" type="fixed">
    <origin rpy="0 0 0" xyz="0 -0.05 0"/>
    <parent link="camera_link"/>
    <child link="camera_infra2_frame"/>
  </joint>
  <link name="camera_infra2_frame"/>
  <joint name="camera_infra2_optical_joint" type="fixed">
    <origin rpy="-1.5707963267948966 0 -1.5707963267948966" xyz="0 0 0"/>
    <parent link="camera_infra2_frame"/>
    <child link="camera_infra2_optical_frame"/>
  </joint>
  <link name="camera_infra2_optical_frame"/>
  <!-- camera color joints and links -->
  <joint name="camera_color_joint" type="fixed">
    <origin rpy="0 0 0" xyz="0 0.015 0"/>
    <parent link="camera_link"/>
    <child link="camera_color_frame"/>
  </joint>
  <link name="camera_color_frame"/>
  <joint name="camera_color_optical_joint" type="fixed">
    <origin rpy="-1.5707963267948966 0 -1.5707963267948966" xyz="0 0 0"/>
    <parent link="camera_color_frame"/>
    <child link="camera_color_optical_frame"/>
  </joint>
  <link name="camera_color_optical_frame"/>
  <link name="box_link">
    <inertial>
      <origin rpy="0 0 0" xyz="0.017247 -0.0057664 0.13638"/>
      <mass value="15"/>
      <inertia ixx="0.019403" ixy="-1.1237E-05" ixz="-0.00039599" iyy="0.066236" iyz="5.3962E-07" izz="0.078079"/>
    </inertial>
    <visual>
      <origin rpy="0 0 0" xyz="0 0 0"/>
      <geometry>
        <mesh filename="../meshes/scout/box_link.STL"/>
      </geometry>
      <material name="">
        <color rgba="1 1 1 1"/>
      </material>
    </visual>
    <collision>
      <origin rpy="0 0 0" xyz="0.02 0 0"/>
      <geometry>
        <mesh filename="../meshes/scout/box_link.STL"/>
      </geometry>
    </collision>
  </link>
  <link name="laser_Link">
    <inertial>
      <origin rpy="0 0 0" xyz="-0.00029458 -1.102E-05 0.035775"/>
      <mass value="0.58508"/>
      <inertia ixx="0.00062907" ixy="-3.4247E-08" ixz="6.994E-08" iyy="0.00063026" iyz="-4.8147E-08" izz="0.00074925"/>
    </inertial>
    <visual>
      <origin rpy="0 0 0" xyz="0 0 0"/>
      <geometry>
        <mesh filename="../meshes/scout/laser_Link.STL"/>
      </geometry>
      <material name="">
        <color rgba="1 1 1 1"/>
      </material>
    </visual>
    <collision>
      <origin rpy="0 0 0" xyz="0 0 0.04"/>
      <geometry>
        <cylinder length="0.09" radius="0.05"/>
      </geometry>
    </collision>
  </link>
  <joint name="laser_joint" type="fixed">
    <origin rpy="0 0 3.14" xyz="-0.37655 0 0.018"/>
    <parent link="box_link"/>
    <child link="laser_Link"/>
    <axis xyz="0 0 0"/>
  </joint>
  <joint name="box_joint" type="fixed">
    <parent link="base_link"/>
    <child link="box_link"/>
    <origin rpy="0.0 0.0 3.14" xyz="0.0 0.0 0"/>
  </joint>
  <joint name="arm_base_joint" type="fixed">
    <parent link="base_link"/>
    <child link="arm_base"/>
    <origin rpy="0.0 0.0 1.5708" xyz="0.1 0 0.24"/>
  </joint>
  <joint name="cr5_with_ag95" type="fixed">
    <origin rpy="0 0 -1.5707963267948966" xyz="0.0 0.0 0.025"/>
    <parent link="Link6"/>
    <child link="dh_robotics_ag95_base_link"/>
  </joint>
</robot>

